# 六、异常

Python 提供了一种非常简洁的方法来处理异常，但是 Python 2 和 3 都有自己独特的异常处理语法。在 Python 3 中，捕捉异常对象需要 as 关键字；用参数引发异常需要括号；并且字符串不能作为异常使用。本章描述如何实现引发、捕获异常和异常链的中立兼容性。

## 引发异常

Python 允许我们使用 raise 语句以多种方式引发异常。其他语言可能会使用 throw。使用 raise 语句时，我们可以指定三个参数，即异常类型、异常参数和回溯。使用不带任何参数的 raise 语句会重新引发上一个异常。引发异常的一般语法是:

```py
raise [Exception [, args [, traceback]]]
```

异常参数和回溯是可选的。让我们看看如何以一种与 Python 2 和 3 都兼容的方式引发异常。我们将首先查看没有追溯的异常，然后查看有追溯的异常。

### 引发不带追溯的异常

引发不带回溯的异常通常涉及到只使用带有异常名(如 NameError)和异常参数的 raise 语句。典型的 Python 2 语法如下所示:

```py
def func(value):
    raise ValueError, "funny value"
```

为了在两个 Python 版本中可靠地执行该语句，应该将其更改为以下代码片段:

```py
def func(value):
   raise ValueError ("funny value")
```

我们在异常参数周围引入括号。

### 通过回溯引发异常

Python 还允许我们通过回溯来引发异常。回溯是从异常处理程序开始的堆栈跟踪，沿着调用链一直到引发异常的地方。以下是使用回溯引发异常的 Python 2 语法:

```py
def func(value):
    traceback = sys.exc_info()[2]
    raise ValueError, "funny value", traceback
```

同样的方法也可以用 Python 3 编写，只是有一点小小的不同:异常参数用括号括起来，调用 with_traceback()方法。

```py
def func(value):
    traceback = sys.exc_info()[2]
    raise ValueError ("funny value").with_traceback(traceback)
```

为了中立的兼容性，Python-future 和 six 都提供了引发异常的包装器。

#### 使用 Python-未来

我们将从 future.utils 包中导入并使用 raise_ 来引发在 Python 2 和 3 上运行的异常。

```py
from future.utils import raise_

def func(value):
    traceback = sys.exc_info()[2]
    raise_ (ValueError, "funny value", traceback)
```

当我们使用 raise_ 时，我们给它异常类型、参数和回溯作为参数。

此外，future 提供了使用 future.utils 包中的 raise_with_traceback 方法来实现相同功能的选项。

```py
from future.utils import  raise_with_traceback

def func(value):
    raise_with_traceback(ValueError("dodgy value"))
```

#### 使用六

类似地，我们可以从 six 包中导入并使用 raise_ 来引发运行在 Python 2 和 3 上的异常。

```py
from six import raise_

def func(value):
    traceback = sys.exc_info()[2]
    raise_ (ValueError, "funny value", traceback)
```

当我们使用 raise_ 时，我们给它异常类型、参数和回溯作为参数。

总之，当提出兼容性异常时

*   没有回溯的异常会在异常参数周围引入括号

*   带回溯的异常使用 raise_ from Python-future 和 six

## 捕捉异常

我们需要一个 catch-all except 子句来捕捉 Python 中的异常。try 和 except 是用于捕捉异常的 Python 关键字。try 子句中的代码是逐语句执行的。如果发生异常，将跳过 try 块的其余部分，并执行 except 子句。

这是在 Python 2 中捕捉异常的一种简单方法:

```py
(x,y) = (5,0)

try:
        z = x/y
except ZeroDivisionError, e:
        print e
```

except 子句可以将多个异常命名为带括号的元组；例如，(ZerDivionError，IdontLikeYouException)。在分隔异常和 *e* 变量的逗号之前。

在 Python 2 中，用逗号将异常与变量分开是可行的，但在 Python 3 中，这种做法已被弃用，并且不可行。为了中性兼容性，请使用 as 关键字而不是逗号。这是 Python 3 中的默认语法，但它在两个 Python 版本中都适用。

```py
(x,y) = (5,0)
try:
    z = x/y
except ZeroDivisionError as e:
    z = e
    print z
```

as 关键字将异常分配给一个变量，比如我们的例子中的 *e* ，这也是最常见的，但是您可以给这个变量一个不同的名称。该变量是一个异常实例。

总之，使用 as 关键字(而不是逗号)是为了在捕获异常时保持兼容性。

## 异常链接

异常链在将捕获的异常包装在新异常中后重新引发该异常。原始异常被保存为新异常的属性。如果一个异常引起另一个异常，异常链是隐式的。这意味着第一个异常的信息在堆栈跟踪中是可用的，因为它存储在最后一个异常类的 __context__ 属性中。如果我们在异常出现时关联一个新的异常，异常链也可能是显式的。这用于将一种异常类型转换成另一种。原始异常类型存储在 __cause__ 属性中。

异常链接只在 Python 3 中可用，在 Python 3 中，我们可以编写以下代码:

```py
Download PackageImports/exceptionchaining_Python3.py
try:
    v = {}['a']
except KeyError as e:
    raise ValueError('failed') from e
```

在 Python 2 中没有实现异常链接的直接方法，但是我们可以通过向异常类添加自定义属性来实现同样的目的，如下所示:

```py
Download PackageImports/exceptionchaining_Python2.py

class MyError(Exception):
    def __init__(self, message, cause):
        super(MyError, self).__init__(message + u', caused by ' + repr(cause))
        self.cause = cause

try:
    v = {}['a']
except KeyError as e:
    raise MyError('failed', e)
```

我们将自定义属性添加到 MyError 类中。对于中性代码库，Python-future 和 six 都提供了一个 raise_from 包装器来处理异常链接。

### 使用 Python-未来

我们将从 future.utils 包中导入并使用 raise_from 模块。

```py
Download PackageImports/exceptionchaining_future.py

from future.utils import raise_from

try:
    v = {}['a']
except KeyError as e:
    raise_from (MyError('failed', e))
```

raise_from 包装器替换了 raise 关键字。

#### 使用六

我们将从 six 包中导入并使用 raise_from 模块。

```py
Download PackageImports/exceptionchaining_six.py

from six import raise_from

try:
    v = {}['a']
except KeyError as e:
    raise_from (MyError('failed', e))
```

raise_from 包装器替换了 raise 关键字。

总之，使用 Python-future 的和 six 的 raise_from 包装器在异常链中实现兼容性。

## 摘要

我们研究了如何在 Python 2 代码库中支持 Python 3 来引发和捕捉异常，以及异常链接。

###### 任务:阿里随机方法

今天，Ali 给你发了一封关于 Python 2 脚本的电子邮件，他希望你努力使它与 Python 3 兼容。

```py
**Download PackageImports/task.py** 

def foo(i):
     l = [1,2,3]
     try:
         assert i >= 1
         return l[i]
     except TypeError,e:                                 
        print "dealing with TypeError"
     except IndexError, e:                               
         print "dealing with IndexError"
     except:                                                        
         print "oh dear"
     finally:                                                          
         print "the end"
```

他声称这个脚本的唯一问题是实现异常的方式。他们仍然使用 Python 2 语法，这在 Python 3 中不起作用。

以下内容已被合并。

```py
**Download PackageImports/solution.py** 

def foo(i):
     l = [1,2,3]
     try:
         assert i >= 1
         return l[i]
     except TypeError as e:                                 
        print "dealing with TypeError"
     except IndexError as e:                               
         print "dealing with IndexError"
     except:                                                        
         print "oh dear"
     finally:                                                          
         print "the end"
```

语法已更改为使用 as，而不是不推荐使用的 Python 2 逗号。